<?xml version="1.0"?>

<robot xmlns:xacro="http://www.ros.org/wiki/xacro" name="my_bot">
    
    <link name="base_footprint"/>
    
    
    <link name="base_link">
        <visual>
            <origin rpy="0 0 0" xyz="0 0 0"/>
            <geometry>
                <mesh filename="package://my_bot_description/meshes/base_link.stl"/>
            </geometry>
        </visual>
    
    </link>
    <joint name="base_joint" type="fixed">
        <parent link="base_footprint"/>
        <child link="base_link"/>
        <origin rpy="0 0 0" xyz="0 0 0.033"/>

    
    </joint>
    <link name="wheel_right_link">
        <visual>
            <origin rpy="1.57 0 0" xyz="0 0 0"/>
            <geometry>
                <mesh filename="package://my_bot_description/meshes/wheel_right_link.stl"/>
            </geometry>
        </visual>
    </link>
    
    <joint name="wheel_right_joint" type="continuous">
        <parent link="base_link"/>
        <child link="wheel_right_link"/>
        <origin rpy="0 0 0" xyz="0 -0.07 0"/>
        <axis xyz="0 1 0"/>
    </joint>

    <link name="wheel_left_link">
        <visual>
            <origin rpy="-1.57 0 0" xyz="0 0 0"/>
            <geometry>
                <mesh filename="package://my_bot_description/meshes/wheel_left_link.stl"/>
            </geometry>
        </visual>
    </link>
    
    <joint name="wheel_left_joint" type="continuous">
        <parent link="base_link"/>
        <child link="wheel_left_link"/>
        <origin rpy="0 0 0" xyz="0 0.07 0"/>
        <axis xyz="0 1 0"/>
    </joint>

    <link name="castor_front_link">
        <visual>
            <geometry>
                <origin rpy="0 0 0" xyz="0 0 0"/>
                <mesh filename="package://my_bot_description/meshes/castor_front_link.stl"/>
            </geometry>
        </visual>
    </link>

    <joint name="castor_front_joint" type="fixed">
        <parent link="base_link"/>
        <child link="castor_front_link"/>
        <origin rpy="0 0 0" xyz="0.04755 0 -0.0275"/>
    </joint>
    
    <link name="castor_rear_link">
        <visual>
            <geometry>
                <origin rpy="0 0 0" xyz="0 0 0"/>
                <!mesh filename="package://my_bot_description/meshes/castor_rear_link.stl"/>
                <box size="0.02 0.02 0.02"/>
            </geometry>
        </visual>
    </link>

    <joint name="castor_rear_joint" type="fixed">
        <parent link="base_link"/>
        <child link="castor_rear_link"/>
        <origin rpy="0 0 0" xyz="-0.04755 0 -0.0275"/>
    </joint>

    
    

    
    

</robot>